Workbook

Sheet README
A1: Arcadia KPI cards as map layers: configuration
A3: Companion to docs/tableau_kpi_cards_guide.md. Arcadia Systems is fictional; all data is synthetic.
A4: Layout: card positions and anchor coordinates, computed from the parameters (blue cells are inputs; change them and the rest recalculates).
A5: Parameters: the 16 kpi_ parameters to create in Tableau.
A6: Calcs: every calculated field, in creation order, copy-ready.
A7: Layers: the 17 text layers plus the Frame and Check helpers, with fonts and colors.
A8: Dashboard: dashboard, image and sheet placement.
A9: Validation: the FY26 values each card must show.
A10: Note: written without access to Tableau Public; tune kpi_FitX and kpi_FitY on screen (guide Section 6).

Sheet Parameters
A1: Name | B1: Default | C1: Purpose
A2: kpi_Scale | B2: 0.010986328 | C2: Degrees per pixel at zoom 7: 360/(256*2^7). Do not change
A3: kpi_SheetW | B3: 1400 | C3: Sheet width px
A4: kpi_SheetH | B4: 110 | C4: Sheet height px
A5: kpi_FitX | B5: 1.1 | C5: Calibrate on screen
A6: kpi_FitY | B6: 1.1 | C6: Calibrate on screen
A7: kpi_ShiftX | B7: 0 | C7: Nudge px
A8: kpi_ShiftY | B8: 0 | C8: Nudge px
A9: kpi_GridLeft | B9: 56 | C9: Card 1 left edge
A10: kpi_GridTop | B10: 12 | C10: Card top edge
A11: kpi_CardW | B11: 244
A12: kpi_CardH | B12: 86
A13: kpi_GapX | B13: 17 | C13: Space between cards
A14: kpi_PadX | B14: 16 | C14: Text inset
A15: kpi_TitleDY | B15: 17 | C15: Title center below card top
A16: kpi_ValueDY | B16: 44 | C16: Value center
A17: kpi_SubDY | B17: 71 | C17: Note center

Sheet Layout
A1: Card | B1: Left px | C1: Title lon | D1: Value lon | E1: Note lon | F1: Raw offset within 91% of half-width?
A2: Card 1 | B2: =Parameters!$B$9+0*(Parameters!$B$11+Parameters!$B$13) | C2: =($B2+Parameters!$B$14+Parameters!$B$7-Parameters!$B$3/2)*Parameters!$B$2*Parameters!$B$5 | D2: =($B2+Parameters!$B$14+Parameters!$B$7-Parameters!$B$3/2)*Parameters!$B$2*Parameters!$B$5 | E2: =($B2+Parameters!$B$14+Parameters!$B$7-Parameters!$B$3/2)*Parameters!$B$2*Parameters!$B$5 | F2: =IF(ABS($B2+Parameters!$B$14-Parameters!$B$3/2)<=0.91*Parameters!$B$3/2,"yes","NO")
A3: Card 2 | B3: =Parameters!$B$9+1*(Parameters!$B$11+Parameters!$B$13) | C3: =($B3+Parameters!$B$14+Parameters!$B$7-Parameters!$B$3/2)*Parameters!$B$2*Parameters!$B$5 | D3: =($B3+Parameters!$B$14+Parameters!$B$7-Parameters!$B$3/2)*Parameters!$B$2*Parameters!$B$5 | E3: =($B3+Parameters!$B$14+Parameters!$B$7-Parameters!$B$3/2)*Parameters!$B$2*Parameters!$B$5 | F3: =IF(ABS($B3+Parameters!$B$14-Parameters!$B$3/2)<=0.91*Parameters!$B$3/2,"yes","NO")
A4: Card 3 | B4: =Parameters!$B$9+2*(Parameters!$B$11+Parameters!$B$13) | C4: =($B4+Parameters!$B$14+Parameters!$B$7-Parameters!$B$3/2)*Parameters!$B$2*Parameters!$B$5 | D4: =($B4+Parameters!$B$14+Parameters!$B$7-Parameters!$B$3/2)*Parameters!$B$2*Parameters!$B$5 | E4: =($B4+Parameters!$B$14+Parameters!$B$7-Parameters!$B$3/2)*Parameters!$B$2*Parameters!$B$5 | F4: =IF(ABS($B4+Parameters!$B$14-Parameters!$B$3/2)<=0.91*Parameters!$B$3/2,"yes","NO")
A5: Card 4 | B5: =Parameters!$B$9+3*(Parameters!$B$11+Parameters!$B$13) | C5: =($B5+Parameters!$B$14+Parameters!$B$7-Parameters!$B$3/2)*Parameters!$B$2*Parameters!$B$5 | D5: =($B5+Parameters!$B$14+Parameters!$B$7-Parameters!$B$3/2)*Parameters!$B$2*Parameters!$B$5 | E5: =($B5+Parameters!$B$14+Parameters!$B$7-Parameters!$B$3/2)*Parameters!$B$2*Parameters!$B$5 | F5: =IF(ABS($B5+Parameters!$B$14-Parameters!$B$3/2)<=0.91*Parameters!$B$3/2,"yes","NO")
A6: Card 5 | B6: =Parameters!$B$9+4*(Parameters!$B$11+Parameters!$B$13) | C6: =($B6+Parameters!$B$14+Parameters!$B$7-Parameters!$B$3/2)*Parameters!$B$2*Parameters!$B$5 | D6: =($B6+Parameters!$B$14+Parameters!$B$7-Parameters!$B$3/2)*Parameters!$B$2*Parameters!$B$5 | E6: =($B6+Parameters!$B$14+Parameters!$B$7-Parameters!$B$3/2)*Parameters!$B$2*Parameters!$B$5 | F6: =IF(ABS($B6+Parameters!$B$14-Parameters!$B$3/2)<=0.91*Parameters!$B$3/2,"yes","NO")
A8: Row | B8: Center y px | C8: Latitude | D8: In 91% of centre?
A9: Title | B9: =Parameters!$B$10+Parameters!$B$15 | C9: =-(B9+Parameters!$B$8-Parameters!$B$4/2)*Parameters!$B$2*Parameters!$B$6 | D9: =IF(ABS(B9-Parameters!$B$4/2)<=0.91*Parameters!$B$4/2,"yes","NO")
A10: Value | B10: =Parameters!$B$10+Parameters!$B$16 | C10: =-(B10+Parameters!$B$8-Parameters!$B$4/2)*Parameters!$B$2*Parameters!$B$6 | D10: =IF(ABS(B10-Parameters!$B$4/2)<=0.91*Parameters!$B$4/2,"yes","NO")
A11: Note | B11: =Parameters!$B$10+Parameters!$B$17 | C11: =-(B11+Parameters!$B$8-Parameters!$B$4/2)*Parameters!$B$2*Parameters!$B$6 | D11: =IF(ABS(B11-Parameters!$B$4/2)<=0.91*Parameters!$B$4/2,"yes","NO")

Sheet Calcs
A1: Field | B1: Formula | C1: Note
A2: K Valid | B2: [Start Month] <= [End Month] | C2: a start after the end is meaningless
A3: K Open HC | B3: ZN(SUM(IF [In Range] AND [Movement Category] = "Opening" AND [Month End Date] = [Start Month] THEN [Headcount] END))
A4: K Close HC | B4: ZN(SUM(IF [In Range] AND [Movement Category] = "Closing" AND [Month End Date] = [End Month] THEN [Headcount] END))
A5: K Close FTE | B5: ZN(SUM(IF [In Range] AND [Movement Category] = "Closing" AND [Month End Date] = [End Month] THEN [Fte] END))
A6: K Net Pct | B6: IF [K Open HC] = 0 THEN 0 ELSE ([K Close HC] - [K Open HC]) / [K Open HC] END
A7: K Hires | B7: ZN([Hires])
A8: K Leavers Vol | B8: ZN([Voluntary Leavers])
A9: K Moves | B9: ZN([Internal Moves])
A10: K Promotions | B10: ZN(SUM(IF [In Range] AND [Movement Category] = "Internal Moves In" AND [Movement Reason] = "Promotion" THEN [Headcount] END))
A11: K Other Moves | B11: [K Moves] - [K Promotions]
A12: K Part Time Gap | B12: [K Close HC] - [K Close FTE] | C12: headcount minus FTE
A13: K Open Str | B13: IF [K Open HC] >= 1000 THEN STR(DIV(INT([K Open HC]), 1000)) + "," + RIGHT("00" + STR(INT([K Open HC]) % 1000), 3) ELSE STR(INT([K Open HC])) END | C13: 12510 -> "12,510"
A14: K Net Pct Str | B14: STR(DIV(INT(ROUND(ABS([K Net Pct]) * 1000, 0)), 10)) + "." + STR(INT(ROUND(ABS([K Net Pct]) * 1000, 0)) % 10) + "%" | C14: 0.055 -> "5.5%"; sign handled by the note
A15: KPI 1 Value | B15: IF NOT [K Valid] THEN "—" ELSEIF [K Close HC] >= 1000 THEN STR(DIV(INT([K Close HC]), 1000)) + "," + RIGHT("00" + STR(INT([K Close HC]) % 1000), 3) ELSE STR(INT([K Close HC])) END
A16: KPI 1 Note Up | B16: IF [K Valid] AND [K Net Pct] > 0 THEN "+" + [K Net Pct Str] END | C16: teal text
A17: KPI 1 Note Down | B17: IF [K Valid] AND [K Net Pct] < 0 THEN "−" + [K Net Pct Str] END | C17: dark coral text
A18: KPI 1 Note Flat | B18: IF [K Valid] AND [K Net Pct] = 0 THEN [K Net Pct Str] END | C18: slate text
A19: KPI 1 Note Rest | B19: IF [K Valid] THEN "vs " + [K Open Str] + " at start" END | C19: slate, Tableau Book
A20: KPI 2 Value | B20: IF NOT [K Valid] THEN "—" ELSEIF ROUND([K Close FTE], 0) >= 1000 THEN STR(DIV(INT(ROUND([K Close FTE], 0)), 1000)) + "," + RIGHT("00" + STR(INT(ROUND([K Close FTE], 0)) % 1000), 3) ELSE STR(INT(ROUND([K Close FTE], 0))) END | C20: 12,940.0: round to tenths, then split whole and tenth
A21: KPI 2 Note | B21: IF NOT [K Valid] THEN "" ELSE IF INT(ROUND([K Part Time Gap], 0)) >= 1000 THEN STR(DIV(INT(ROUND([K Part Time Gap], 0)), 1000)) + "," + RIGHT("00" + STR(INT(ROUND([K Part Time Gap], 0)) % 1000), 3) ELSE STR(INT(ROUND([K Part Time Gap], 0))) END + " below headcount (part-time)" END
A22: KPI 3 Value | B22: IF NOT [K Valid] THEN "—" ELSEIF [K Hires] >= 1000 THEN STR(DIV(INT([K Hires]), 1000)) + "," + RIGHT("00" + STR(INT([K Hires]) % 1000), 3) ELSE STR(INT([K Hires])) END | C22: the comma pattern on [K Hires]
A23: KPI 3 Note | B23: IF NOT [K Valid] THEN "" ELSE STR(DIV(INT(ROUND(ZN([Hire Rate (annualized)]) * 1000, 0)), 10)) + "." + STR(INT(ROUND(ZN([Hire Rate (annualized)]) * 1000, 0)) % 10) + "% annualized hire rate" END | C23: the percent pattern on the annualized hire rate
A24: KPI 4 Value | B24: IF NOT [K Valid] OR [Average Headcount] < 20 THEN "—" ELSE STR(DIV(INT(ROUND([Voluntary Turnover (annualized)] * 1000, 0)), 10)) + "." + STR(INT(ROUND([Voluntary Turnover (annualized)] * 1000, 0)) % 10) + "%" END | C24: hidden for groups under 20 people, like Rate Shown
A25: KPI 4 Note | B25: IF NOT [K Valid] THEN "" ELSE IF [K Leavers Vol] >= 1000 THEN STR(DIV(INT([K Leavers Vol]), 1000)) + "," + RIGHT("00" + STR(INT([K Leavers Vol]) % 1000), 3) ELSE STR(INT([K Leavers Vol])) END + " leavers by choice" END | C25: the comma pattern on [K Leavers Vol]
A26: KPI 5 Value | B26: IF NOT [K Valid] THEN "—" ELSEIF [K Moves] >= 1000 THEN STR(DIV(INT([K Moves]), 1000)) + "," + RIGHT("00" + STR(INT([K Moves]) % 1000), 3) ELSE STR(INT([K Moves])) END | C26: the comma pattern on [K Moves]
A27: KPI 5 Note | B27: IF NOT [K Valid] THEN "" ELSE IF [K Promotions] >= 1000 THEN STR(DIV(INT([K Promotions]), 1000)) + "," + RIGHT("00" + STR(INT([K Promotions]) % 1000), 3) ELSE STR(INT([K Promotions])) END + " promotions · " + IF [K Other Moves] >= 1000 THEN STR(DIV(INT([K Other Moves]), 1000)) + "," + RIGHT("00" + STR(INT([K Other Moves]) % 1000), 3) ELSE STR(INT([K Other Moves])) END + " other moves" END
A28: kpi_lat Title | B28: -([kpi_GridTop] + [kpi_TitleDY] + [kpi_ShiftY] - [kpi_SheetH] / 2) * [kpi_Scale] * [kpi_FitY]
A29: kpi_lat Value | B29: -([kpi_GridTop] + [kpi_ValueDY] + [kpi_ShiftY] - [kpi_SheetH] / 2) * [kpi_Scale] * [kpi_FitY]
A30: kpi_lat Sub | B30: -([kpi_GridTop] + [kpi_SubDY] + [kpi_ShiftY] - [kpi_SheetH] / 2) * [kpi_Scale] * [kpi_FitY]
A31: kpi_lon C1 | B31: ([kpi_GridLeft] + 0 * ([kpi_CardW] + [kpi_GapX]) + [kpi_PadX] + [kpi_ShiftX] - [kpi_SheetW] / 2) * [kpi_Scale] * [kpi_FitX]
A32: kpi_lon C2 | B32: ([kpi_GridLeft] + 1 * ([kpi_CardW] + [kpi_GapX]) + [kpi_PadX] + [kpi_ShiftX] - [kpi_SheetW] / 2) * [kpi_Scale] * [kpi_FitX]
A33: kpi_lon C3 | B33: ([kpi_GridLeft] + 2 * ([kpi_CardW] + [kpi_GapX]) + [kpi_PadX] + [kpi_ShiftX] - [kpi_SheetW] / 2) * [kpi_Scale] * [kpi_FitX]
A34: kpi_lon C4 | B34: ([kpi_GridLeft] + 3 * ([kpi_CardW] + [kpi_GapX]) + [kpi_PadX] + [kpi_ShiftX] - [kpi_SheetW] / 2) * [kpi_Scale] * [kpi_FitX]
A35: kpi_lon C5 | B35: ([kpi_GridLeft] + 4 * ([kpi_CardW] + [kpi_GapX]) + [kpi_PadX] + [kpi_ShiftX] - [kpi_SheetW] / 2) * [kpi_Scale] * [kpi_FitX]
A36: kpi_pt Title 1 | B36: MAKEPOINT([kpi_lat Title], [kpi_lon C1]) | C36: anchor point (Note uses kpi_lat Sub)
A37: kpi_pt Title 2 | B37: MAKEPOINT([kpi_lat Title], [kpi_lon C2]) | C37: anchor point (Note uses kpi_lat Sub)
A38: kpi_pt Title 3 | B38: MAKEPOINT([kpi_lat Title], [kpi_lon C3]) | C38: anchor point (Note uses kpi_lat Sub)
A39: kpi_pt Title 4 | B39: MAKEPOINT([kpi_lat Title], [kpi_lon C4]) | C39: anchor point (Note uses kpi_lat Sub)
A40: kpi_pt Title 5 | B40: MAKEPOINT([kpi_lat Title], [kpi_lon C5]) | C40: anchor point (Note uses kpi_lat Sub)
...

Sheet Layers
A1: Layer | B1: Spatial field | C1: Mark | D1: Label | E1: Font | F1: Color
A2: Title 1 | B2: kpi_pt Title 1 | C2: Circle, smallest, opacity 0% | D2: Label field: KPI 1 Title | E2: Tableau Semibold 8pt | F2: #5A6170
A3: Value 1 | B3: kpi_pt Value 1 | C3: Circle, smallest, opacity 0% | D3: Label field: KPI 1 Value | E3: Tableau Bold 20pt | F3: #13233A
A4: Note 1 | B4: kpi_pt Note 1 | C4: Circle, smallest, opacity 0% | D4: Label line: <KPI 1 Note Up><KPI 1 Note Down><KPI 1 Note Flat> <KPI 1 Note Rest> (typed space before Rest) | E4: Tableau Book 8pt | F4: Up #006B66 / Down #B8401F / Flat #5A6170 / Rest #5A6170 (color each field)
A5: Title 2 | B5: kpi_pt Title 2 | C5: Circle, smallest, opacity 0% | D5: Label field: KPI 2 Title | E5: Tableau Semibold 8pt | F5: #5A6170
A6: Value 2 | B6: kpi_pt Value 2 | C6: Circle, smallest, opacity 0% | D6: Label field: KPI 2 Value | E6: Tableau Bold 20pt | F6: #13233A
A7: Note 2 | B7: kpi_pt Note 2 | C7: Circle, smallest, opacity 0% | D7: Label field: KPI 2 Note | E7: Tableau Book 8pt | F7: #5A6170
A8: Title 3 | B8: kpi_pt Title 3 | C8: Circle, smallest, opacity 0% | D8: Label field: KPI 3 Title | E8: Tableau Semibold 8pt | F8: #5A6170
A9: Value 3 | B9: kpi_pt Value 3 | C9: Circle, smallest, opacity 0% | D9: Label field: KPI 3 Value | E9: Tableau Bold 20pt | F9: #13233A
A10: Note 3 | B10: kpi_pt Note 3 | C10: Circle, smallest, opacity 0% | D10: Label field: KPI 3 Note | E10: Tableau Book 8pt | F10: #5A6170
A11: Title 4 | B11: kpi_pt Title 4 | C11: Circle, smallest, opacity 0% | D11: Label field: KPI 4 Title | E11: Tableau Semibold 8pt | F11: #5A6170
A12: Value 4 | B12: kpi_pt Value 4 | C12: Circle, smallest, opacity 0% | D12: Label field: KPI 4 Value | E12: Tableau Bold 20pt | F12: #13233A
... A16: Note 5 | B16: kpi_pt Note 5 | C16: Circle, smallest, opacity 0% | D16: Label field: KPI 5 Note | E16: Tableau Book 8pt | F16: #5A6170
A17: Corner TL | B17: kpi_Corner TL | C17: Circle, smallest, opacity 0% | D17: (no label)
A18: Corner BR | B18: kpi_Corner BR | C18: Circle, smallest, opacity 0% | D18: (no label)
A19: ALL text layers | D19: Alignment: Horizontal Right, Vertical Middle (Right makes the text start at the point)

Sheet Dashboard
A1: Setting | B1: Value
A2: Dashboard size | B2: Fixed 1400 x 850
A3: Page background | B3: #F3F3EF
A4: Background image | B4: docs/brand/arcadia_kpi_cards_bg.png, Floating, x 0 y 78 w 1400 h 110, Fit Image on, Center Image off
A5: KPI Cards sheet | B5: Floating, x 0 y 78 w 1400 h 110, above the image, background None, title hidden
A6: Side gutter | B6: 56 px for every object
A7: Map options | B7: Background None; search, toolbar, pan/zoom off; tooltips off

Sheet Validation
A1: Card | B1: Value | C1: Note
A2: Closing headcount | B2: 13,201 | C2: +5.5% vs 12,510 at start
A3: Closing FTE | B3: 12,940 | C3: 261 below headcount (part-time)
A4: Hires | B4: 2,354 | C4: 18.3% annualized hire rate
A5: Voluntary turnover (annualized) | B5: 10.4% | C5: 1,341 leavers by choice
A6: Internal moves | B6: 1,615 | C6: 1,038 promotions · 577 other moves
A8: Range: Start Month 2025-07-31, End Month 2026-06-30. Start after End: every value shows an em dash.

Sheet Grid
A1: # | B1: Item | C1: Type | D1: x | E1: y | F1: w | G1: h | H1: Notes
A2: 1 | B2: Header band | C2: Blank | D2: 0 | E2: 0 | F2: 1400 | G2: 76 | H2: Background #13233A
A3: 2 | B3: Logo | C3: Image | D3: 56 | E3: 14 | F3: 177 | G3: 48 | H3: arcadia_logo_horizontal_reverse.png
A4: 3 | B4: Title and subtitle | C4: Text | D4: 256 | E4: 10 | F4: 470 | G4: 58 | H4: White title; subtitle #C9D1DC
A5: 4 | B5: Start Month | C5: Parameter control | D5: 744 | E5: 22 | F5: 140 | G5: 32 | H5: Compact dropdown, white bg
A6: 5 | B6: End Month | C6: Parameter control | D6: 892 | E6: 22 | F6: 140 | G6: 32
A7: 6 | B7: Headcount / FTE pills | C7: Sheet (Measure Toggle) | D7: 1044 | E7: 22 | F7: 150 | G7: 32
A8: 7 | B8: Methodology pill | C8: Sheet | D8: 1204 | E8: 22 | F8: 140 | G8: 32
A9: 8 | B9: KPI card background | C9: Image | D9: 0 | E9: 78 | F9: 1400 | G9: 110 | H9: arcadia_kpi_cards_bg.png
A10: 9 | B10: KPI cards | C10: Sheet | D10: 0 | E10: 78 | F10: 1400 | G10: 110 | H10: above the image
A11: 10 | B11: Waterfall card | C11: Sheet or Blank | D11: 56 | E11: 188 | F11: 780 | G11: 624
A12: 11 | B12: Headcount trend card | C12: Sheet or Blank | D12: 848 | E12: 188 | F12: 496 | G12: 300
A13: 12 | B13: Turnover by function card | C13: Sheet or Blank | D13: 848 | E13: 500 | F13: 496 | G13: 312
A14: 14 | B14: Footer note | C14: Text | D14: 56 | E14: 820 | F14: 1288 | G14: 22 | H14: Slate #5A6170, 8 pt
A15: 13 | B15: Waterfall caption | C15: Sheet | D15: 68 | E15: 756 | F15: 756 | G15: 48 | H15: Over the waterfall card's bottom padding; waterfall sheet bottom inner padding 64
